<mujoco model="bottle_cap_arena">
  <compiler angle="radian" autolimits="true"/>
  <option timestep="0.004" gravity="0 0 -9.81"/>

  <statistic center="0 0 0.25" extent="1.9"/>

  <visual>
    <headlight diffuse="0.8 0.8 0.8" ambient="0.40 0.40 0.40" specular="0 0 0"/>
    <rgba haze="0.10 0.12 0.12 1"/>
    <global azimuth="145" elevation="-38"/>
  </visual>

  <asset>
    <texture name="floor_tex" type="2d" builtin="checker" rgb1="0.92 0.92 0.92" rgb2="0.84 0.84 0.84" width="512" height="512"/>
    <material name="floor_mat" texture="floor_tex" texrepeat="8 8" reflectance="0.04"/>
  </asset>

  <worldbody>

    <!-- Floor -->
    <geom name="floor" type="plane" size="3 3 0.1" material="floor_mat"/>

    <!-- Yellow floor tape (arena boundary) -->
    <geom name="tape_n" type="box" size="0.8950 0.0200 0.0015" pos="0.0000 0.9000 0.0015" rgba="1.0 0.92 0.0 1"/>
    <geom name="tape_s" type="box" size="0.8950 0.0200 0.0015" pos="0.0000 -0.9000 0.0015" rgba="1.0 0.92 0.0 1"/>
    <geom name="tape_e" type="box" size="0.0200 0.9200 0.0015" pos="0.8750 0.0000 0.0015" rgba="1.0 0.92 0.0 1"/>
    <geom name="tape_w" type="box" size="0.0200 0.9200 0.0015" pos="-0.8750 0.0000 0.0015" rgba="1.0 0.92 0.0 1"/>

    <!-- Crate obstacles -->
    <geom name="crate_small" type="box" size="0.1000 0.1500 0.1250" pos="-0.3200 0.0000 0.1250" rgba="0.15 0.35 0.85 1.0"/>
    <geom name="crate_large" type="box" size="0.1500 0.2000 0.1500" pos="0.3700 0.0000 0.1500" rgba="0.15 0.7 0.25 1.0"/>

    <!-- Gray collection basket (centre of arena) -->
    <geom name="basket_floor" type="box" size="0.1100 0.1100 0.0100" pos="0.0000 0.0000 0.0100" rgba="0.48 0.48 0.48 1"/>
    <geom name="basket_wall_n" type="box" size="0.1100 0.0100 0.0400" pos="0.0000 0.1100 0.0600" rgba="0.48 0.48 0.48 1"/>
    <geom name="basket_wall_s" type="box" size="0.1100 0.0100 0.0400" pos="0.0000 -0.1100 0.0600" rgba="0.48 0.48 0.48 1"/>
    <geom name="basket_wall_e" type="box" size="0.0100 0.1000 0.0400" pos="0.1100 0.0000 0.0600" rgba="0.48 0.48 0.48 1"/>
    <geom name="basket_wall_w" type="box" size="0.0100 0.1000 0.0400" pos="-0.1100 0.0000 0.0600" rgba="0.48 0.48 0.48 1"/>

    <!-- JETANK robot digital twin (visual placeholder) -->
    <body name="robot" pos="-0.6500 -0.6500 0.1250">
      <freejoint name="robot_free"/>
      <geom name="chassis" type="box" size="0.0790 0.0850 0.1250" rgba="0.16 0.16 0.16 1" mass="1.8"/>
      <geom name="track_l" type="box" size="0.0890 0.0150 0.1310" pos="0.0000 0.0880 0.0000" rgba="0.07 0.07 0.07 1" mass="0.25"/>
      <geom name="tread_l_55" type="box" size="0.0100 0.0160 0.0040" pos="-0.0550 0.1030 -0.1290" rgba="0.13 0.13 0.13 1"/>
      <geom name="tread_l_20" type="box" size="0.0100 0.0160 0.0040" pos="-0.0200 0.1030 -0.1290" rgba="0.13 0.13 0.13 1"/>
      <geom name="tread_l_15" type="box" size="0.0100 0.0160 0.0040" pos="0.0150 0.1030 -0.1290" rgba="0.13 0.13 0.13 1"/>
      <geom name="tread_l_50" type="box" size="0.0100 0.0160 0.0040" pos="0.0500 0.1030 -0.1290" rgba="0.13 0.13 0.13 1"/>
      <geom name="track_r" type="box" size="0.0890 0.0150 0.1310" pos="0.0000 -0.0880 0.0000" rgba="0.07 0.07 0.07 1" mass="0.25"/>
      <geom name="tread_r_55" type="box" size="0.0100 0.0160 0.0040" pos="-0.0550 -0.1030 -0.1290" rgba="0.13 0.13 0.13 1"/>
      <geom name="tread_r_20" type="box" size="0.0100 0.0160 0.0040" pos="-0.0200 -0.1030 -0.1290" rgba="0.13 0.13 0.13 1"/>
      <geom name="tread_r_15" type="box" size="0.0100 0.0160 0.0040" pos="0.0150 -0.1030 -0.1290" rgba="0.13 0.13 0.13 1"/>
      <geom name="tread_r_50" type="box" size="0.0100 0.0160 0.0040" pos="0.0500 -0.1030 -0.1290" rgba="0.13 0.13 0.13 1"/>
      <geom name="hub_fl" type="cylinder" size="0.0875 0.0170" pos="0.0850 0.0910 0.0000" euler="1.5708 0.0000 0.0000" rgba="0.20 0.20 0.20 1"/>
      <geom name="hub_fr" type="cylinder" size="0.0875 0.0170" pos="0.0850 -0.0910 0.0000" euler="1.5708 0.0000 0.0000" rgba="0.20 0.20 0.20 1"/>
      <geom name="hub_rl" type="cylinder" size="0.0875 0.0170" pos="-0.0850 0.0910 0.0000" euler="1.5708 0.0000 0.0000" rgba="0.20 0.20 0.20 1"/>
      <geom name="hub_rr" type="cylinder" size="0.0875 0.0170" pos="-0.0850 -0.0910 0.0000" euler="1.5708 0.0000 0.0000" rgba="0.20 0.20 0.20 1"/>
      <geom name="top_deck" type="box" size="0.0750 0.0750 0.0060" pos="0.0000 0.0000 0.1310" rgba="0.22 0.22 0.22 1"/>
      <body name="arm_assembly" pos="0 0 0">
        <joint name="arm_lift" type="slide" axis="0 0 1" range="-0.20 0"/>
        <geom name="cam_housing" type="box" size="0.0200 0.0280 0.0160" pos="0.0870 0.0000 0.0875" rgba="0.12 0.12 0.12 1"/>
        <geom name="cam_lens" type="cylinder" size="0.0090 0.0060" pos="0.1090 0.0000 0.0875" euler="0.0000 1.5708 0.0000" rgba="0.05 0.20 0.55 1"/>
        <geom name="arm_base" type="cylinder" size="0.0200 0.0200" pos="0.0200 0.0000 0.1450" mass="0.08" rgba="0.25 0.25 0.25 1"/>
        <geom name="arm_shoulder" type="box" size="0.0130 0.0130 0.0300" pos="0.0200 0.0000 0.1950" rgba="0.22 0.22 0.22 1"/>
        <geom name="arm_upper" type="box" size="0.0600 0.0110 0.0110" pos="0.0800 0.0000 0.2250" rgba="0.30 0.30 0.30 1"/>
        <geom name="arm_elbow" type="cylinder" size="0.0130 0.0130" pos="0.1400 0.0000 0.2250" euler="1.5708 0.0000 0.0000" rgba="0.25 0.25 0.25 1"/>
        <geom name="arm_forearm" type="box" size="0.0420 0.0100 0.0100" pos="0.1820 0.0000 0.2130" rgba="0.30 0.30 0.30 1"/>
        <geom name="arm_wrist" type="box" size="0.0130 0.0130 0.0130" pos="0.2370 0.0000 0.2070" rgba="0.22 0.22 0.22 1"/>
        <geom name="gripper_palm" type="box" size="0.0120 0.0220 0.0080" pos="0.2620 0.0000 0.2070" rgba="0.18 0.18 0.18 1"/>
        <geom name="gripper_l" type="box" size="0.0140 0.0070 0.0060" pos="0.2880 0.0160 0.2030" rgba="0.20 0.20 0.20 1"/>
        <geom name="gripper_r" type="box" size="0.0140 0.0070 0.0060" pos="0.2880 -0.0160 0.2030" rgba="0.20 0.20 0.20 1"/>
        <camera name="wrist_cam" pos="0.2370 0.0000 0.2070" xyaxes="0 -1 0 0 0 1" fovy="80"/>
      </body>
    </body>

    <!-- Bottle caps -->
    <body name="cap_0" pos="0.3862 -0.4206 0.0040">
      <freejoint/>
      <geom type="cylinder" size="0.0156 0.0040" rgba="0.78 0.78 0.78 1.0" mass="0.005"/>
    </body>
    <body name="cap_1" pos="0.2814 0.6442 0.0040">
      <freejoint/>
      <geom type="cylinder" size="0.0187 0.0040" rgba="0.1 0.3 0.9 1.0" mass="0.005"/>
    </body>
    <body name="cap_2" pos="0.0976 0.3552 0.0040">
      <freejoint/>
      <geom type="cylinder" size="0.0180 0.0040" rgba="0.1 0.3 0.9 1.0" mass="0.005"/>
    </body>
    <body name="cap_3" pos="0.4934 -0.8116 0.0040">
      <freejoint/>
      <geom type="cylinder" size="0.0177 0.0040" rgba="0.78 0.78 0.78 1.0" mass="0.005"/>
    </body>
    <body name="cap_4" pos="-0.2545 -0.5661 0.0040">
      <freejoint/>
      <geom type="cylinder" size="0.0185 0.0040" rgba="0.1 0.3 0.9 1.0" mass="0.005"/>
    </body>

  </worldbody>
</mujoco>